<mujoco model="go1_description">
  <compiler angle="radian" meshdir="/home/kami/unitree_rl_dataset/unitree_rl_gym/resources/robots/go1/meshes/"/>
  
  <statistic meansize="0.144785" extent="1.23314" center="0.025392 2.0634e-05 -0.245975"/>
  <default>
    <joint damping="0.001" armature="0.01" frictionloss="0.1"/>
  </default>
  <asset>
    <mesh name="trunk" file="trunk.stl"/>
    <mesh name="hip" file="hip.stl"/>
    <mesh name="thigh_mirror" file="thigh_mirror.stl"/>
    <mesh name="calf" file="calf.stl"/>
    <mesh name="thigh" file="thigh.stl"/>
  </asset>

  <worldbody>
    <body name="base" pos= "0 0 0.34">
      <geom size="0.0005 0.0005 0.0005" type="box" contype="0" conaffinity="0" group="1" density="0"/>
      <!-- 加入浮动关节 -->
      <joint name="floating_base_joint" type="free" limited="false"/>
      <body name="trunk">
        <inertial pos="0.011611 0.004437 0.000108" quat="0.0111952 0.707128 -0.00936504 0.706935" mass="4.8" diaginertia="0.0446939 0.036525 0.0161135"/>
        <geom type="mesh" contype="0" conaffinity="0" group="1" density="0" rgba="0.913725 0.913725 0.847059 1" mesh="trunk"/>
        <geom size="0.1881 0.04675 0.057" type="box" rgba="0.913725 0.913725 0.847059 1"/>
        <body name="imu_link" pos="-0.01592 -0.06659 -0.00617">
          <inertial pos="0 0 0" mass="0.001" diaginertia="0.0001 0.0001 0.0001"/>
          <geom size="0.0005 0.0005 0.0005" type="box" contype="0" conaffinity="0" group="1" density="0" rgba="0.8 0 0 1"/>
        </body>
        <body name="FR_hip" pos="0.1881 -0.04675 0">
          <inertial pos="-0.00541 0.00074 6e-06" quat="0.506126 0.507401 0.493705 0.492582" mass="0.510299" diaginertia="0.000591107 0.000396595 0.000305077"/>
          <joint name="FR_hip_joint" pos="0 0 0" axis="1 0 0" range="-0.802851 0.802851" actuatorfrcrange="-33.5 33.5"/>
          <geom quat="0 1 0 0" type="mesh" contype="0" conaffinity="0" group="1" density="0" rgba="0.913725 0.913725 0.847059 1" mesh="hip"/>
          <geom size="0.046 0.02" pos="0 -0.045 0" quat="0.707107 0.707107 0 0" type="cylinder" rgba="0.913725 0.913725 0.847059 1"/>
          <body name="FR_thigh_shoulder" pos="0 -0.08 0"/>
          <body name="FR_thigh" pos="0 -0.08 0">
            <inertial pos="-0.003468 0.018947 -0.032736" quat="0.999266 0.00067676 -0.0382978 0.000639813" mass="0.898919" diaginertia="0.00542178 0.00514246 0.000998869"/>
            <joint name="FR_thigh_joint" pos="0 0 0" axis="0 1 0" range="-1.0472 4.18879" actuatorfrcrange="-33.5 33.5"/>
            <geom type="mesh" contype="0" conaffinity="0" group="1" density="0" rgba="0.913725 0.913725 0.847059 1" mesh="thigh_mirror"/>
            <geom size="0.1065 0.01225 0.017" pos="0 0 -0.1065" quat="0.707107 0 0.707107 0" type="box" rgba="0.913725 0.913725 0.847059 1"/>
            <body name="FR_calf" pos="0 0 -0.213">
              <inertial pos="0.006286 0.001307 -0.122269" quat="0.764505 0.00891446 0.01674 0.644338" mass="0.158015" diaginertia="0.00362744 0.00361214 2.9993e-05"/>
              <joint name="FR_calf_joint" pos="0 0 0" axis="0 1 0" range="-2.69653 -0.916298" actuatorfrcrange="-33.5 33.5"/>
              <geom type="mesh" contype="0" conaffinity="0" group="1" density="0" rgba="0 0 0 1" mesh="calf"/>
              <geom size="0.1065 0.008 0.008" pos="0 0 -0.1065" quat="0.707107 0 0.707107 0" type="box" rgba="0 0 0 1"/>
              <body name="FR_foot" pos="0 0 -0.213">
                <inertial pos="0 0 0" mass="0.06" diaginertia="9.6e-06 9.6e-06 9.6e-06"/>
                <geom size="0.01" contype="0" conaffinity="0" group="1" density="0" rgba="0 0 0 1"/>
                <geom size="0.02" rgba="0 0 0 1"/>
              </body>
            </body>
          </body>
        </body>
        <body name="FL_hip" pos="0.1881 0.04675 0">
          <inertial pos="-0.00541 -0.00074 6e-06" quat="0.492582 0.493705 0.507401 0.506126" mass="0.510299" diaginertia="0.000591107 0.000396595 0.000305077"/>
          <joint name="FL_hip_joint" pos="0 0 0" axis="1 0 0" range="-0.802851 0.802851" actuatorfrcrange="-33.5 33.5"/>
          <geom type="mesh" contype="0" conaffinity="0" group="1" density="0" rgba="0.913725 0.913725 0.847059 1" mesh="hip"/>
          <geom size="0.046 0.02" pos="0 0.045 0" quat="0.707107 0.707107 0 0" type="cylinder" rgba="0.913725 0.913725 0.847059 1"/>
          <body name="FL_thigh_shoulder" pos="0 0.08 0"/>
          <body name="FL_thigh" pos="0 0.08 0">
            <inertial pos="-0.003468 -0.018947 -0.032736" quat="0.999266 -0.00067676 -0.0382978 -0.000639813" mass="0.898919" diaginertia="0.00542178 0.00514246 0.000998869"/>
            <joint name="FL_thigh_joint" pos="0 0 0" axis="0 1 0" range="-1.0472 4.18879" actuatorfrcrange="-33.5 33.5"/>
            <geom type="mesh" contype="0" conaffinity="0" group="1" density="0" rgba="0.913725 0.913725 0.847059 1" mesh="thigh"/>
            <geom size="0.1065 0.01225 0.017" pos="0 0 -0.1065" quat="0.707107 0 0.707107 0" type="box" rgba="0.913725 0.913725 0.847059 1"/>
            <body name="FL_calf" pos="0 0 -0.213">
              <inertial pos="0.006286 0.001307 -0.122269" quat="0.764505 0.00891446 0.01674 0.644338" mass="0.158015" diaginertia="0.00362744 0.00361214 2.9993e-05"/>
              <joint name="FL_calf_joint" pos="0 0 0" axis="0 1 0" range="-2.69653 -0.916298" actuatorfrcrange="-33.5 33.5"/>
              <geom type="mesh" contype="0" conaffinity="0" group="1" density="0" rgba="0.913725 0.913725 0.847059 1" mesh="calf"/>
              <geom size="0.1065 0.008 0.008" pos="0 0 -0.1065" quat="0.707107 0 0.707107 0" type="box" rgba="0.913725 0.913725 0.847059 1"/>
              <body name="FL_foot" pos="0 0 -0.213">
                <inertial pos="0 0 0" mass="0.06" diaginertia="9.6e-06 9.6e-06 9.6e-06"/>
                <geom size="0.01" contype="0" conaffinity="0" group="1" density="0" rgba="0 0 0 1"/>
                <geom size="0.02" rgba="0 0 0 1"/>
              </body>
            </body>
          </body>
        </body>
        <body name="RR_hip" pos="-0.1881 -0.04675 0">
          <inertial pos="0.00541 0.00074 6e-06" quat="0.493705 0.492582 0.506126 0.507401" mass="0.510299" diaginertia="0.000591107 0.000396595 0.000305077"/>
          <joint name="RR_hip_joint" pos="0 0 0" axis="1 0 0" range="-0.802851 0.802851" actuatorfrcrange="-33.5 33.5"/>
          <geom quat="0 0 0 -1" type="mesh" contype="0" conaffinity="0" group="1" density="0" rgba="0.913725 0.913725 0.847059 1" mesh="hip"/>
          <geom size="0.046 0.02" pos="0 -0.045 0" quat="0.707107 0.707107 0 0" type="cylinder" rgba="0.913725 0.913725 0.847059 1"/>
          <body name="RR_thigh_shoulder" pos="0 -0.08 0"/>
          <body name="RR_thigh" pos="0 -0.08 0">
            <inertial pos="-0.003468 0.018947 -0.032736" quat="0.999266 0.00067676 -0.0382978 0.000639813" mass="0.898919" diaginertia="0.00542178 0.00514246 0.000998869"/>
            <joint name="RR_thigh_joint" pos="0 0 0" axis="0 1 0" range="-1.0472 4.18879" actuatorfrcrange="-33.5 33.5"/>
            <geom type="mesh" contype="0" conaffinity="0" group="1" density="0" rgba="0.913725 0.913725 0.847059 1" mesh="thigh_mirror"/>
            <geom size="0.1065 0.01225 0.017" pos="0 0 -0.1065" quat="0.707107 0 0.707107 0" type="box" rgba="0.913725 0.913725 0.847059 1"/>
            <body name="RR_calf" pos="0 0 -0.213">
              <inertial pos="0.006286 0.001307 -0.122269" quat="0.764505 0.00891446 0.01674 0.644338" mass="0.158015" diaginertia="0.00362744 0.00361214 2.9993e-05"/>
              <joint name="RR_calf_joint" pos="0 0 0" axis="0 1 0" range="-2.69653 -0.916298" actuatorfrcrange="-33.5 33.5"/>
              <geom type="mesh" contype="0" conaffinity="0" group="1" density="0" rgba="0 0 0 1" mesh="calf"/>
              <geom size="0.1065 0.008 0.008" pos="0 0 -0.1065" quat="0.707107 0 0.707107 0" type="box" rgba="0 0 0 1"/>
              <body name="RR_foot" pos="0 0 -0.213">
                <inertial pos="0 0 0" mass="0.06" diaginertia="9.6e-06 9.6e-06 9.6e-06"/>
                <geom size="0.01" contype="0" conaffinity="0" group="1" density="0" rgba="0 0 0 1"/>
                <geom size="0.02" rgba="0 0 0 1"/>
              </body>
            </body>
          </body>
        </body>
        <body name="RL_hip" pos="-0.1881 0.04675 0">
          <inertial pos="0.00541 -0.00074 6e-06" quat="0.507401 0.506126 0.492582 0.493705" mass="0.510299" diaginertia="0.000591107 0.000396595 0.000305077"/>
          <joint name="RL_hip_joint" pos="0 0 0" axis="1 0 0" range="-0.802851 0.802851" actuatorfrcrange="-33.5 33.5"/>
          <geom quat="0 0 1 0" type="mesh" contype="0" conaffinity="0" group="1" density="0" rgba="0.913725 0.913725 0.847059 1" mesh="hip"/>
          <geom size="0.046 0.02" pos="0 0.045 0" quat="0.707107 0.707107 0 0" type="cylinder" rgba="0.913725 0.913725 0.847059 1"/>
          <body name="RL_thigh_shoulder" pos="0 0.08 0"/>
          <body name="RL_thigh" pos="0 0.08 0">
            <inertial pos="-0.003468 -0.018947 -0.032736" quat="0.999266 -0.00067676 -0.0382978 -0.000639813" mass="0.898919" diaginertia="0.00542178 0.00514246 0.000998869"/>
            <joint name="RL_thigh_joint" pos="0 0 0" axis="0 1 0" range="-1.0472 4.18879" actuatorfrcrange="-33.5 33.5"/>
            <geom type="mesh" contype="0" conaffinity="0" group="1" density="0" rgba="0.913725 0.913725 0.847059 1" mesh="thigh"/>
            <geom size="0.1065 0.01225 0.017" pos="0 0 -0.1065" quat="0.707107 0 0.707107 0" type="box" rgba="0.913725 0.913725 0.847059 1"/>
            <body name="RL_calf" pos="0 0 -0.213">
              <inertial pos="0.006286 0.001307 -0.122269" quat="0.764505 0.00891446 0.01674 0.644338" mass="0.158015" diaginertia="0.00362744 0.00361214 2.9993e-05"/>
              <joint name="RL_calf_joint" pos="0 0 0" axis="0 1 0" range="-2.69653 -0.916298" actuatorfrcrange="-33.5 33.5"/>
              <geom type="mesh" contype="0" conaffinity="0" group="1" density="0" rgba="0 0 0 1" mesh="calf"/>
              <geom size="0.1065 0.008 0.008" pos="0 0 -0.1065" quat="0.707107 0 0.707107 0" type="box" rgba="0 0 0 1"/>
              <body name="RL_foot" pos="0 0 -0.213">
                <inertial pos="0 0 0" mass="0.06" diaginertia="9.6e-06 9.6e-06 9.6e-06"/>
                <geom size="0.01" contype="0" conaffinity="0" group="1" density="0" rgba="0 0 0 1"/>
                <geom size="0.02" rgba="0 0 0 1"/>
              </body>
            </body>
          </body>
        </body>
      </body>
    </body>
  </worldbody>
  <!-- 加入电机 -->
  <actuator>
    <!-- <motor name="FL_hip_joint" joint="FL_hip_joint"/>
    <motor name="RL_hip_joint" joint="RL_hip_joint"/>
    <motor name="FR_hip_joint" joint="FR_hip_joint"/>
    <motor name="RR_hip_joint" joint="RR_hip_joint"/>
    <motor name="FL_thigh_joint" joint="FL_thigh_joint"/>
    <motor name="RL_thigh_joint" joint="RL_thigh_joint"/>
    <motor name="FR_thigh_joint" joint="FR_thigh_joint"/>
    <motor name="RR_thigh_joint" joint="RR_thigh_joint"/>
    <motor name="FL_calf_joint" joint="FL_calf_joint"/>
    <motor name="RL_calf_joint" joint="RL_calf_joint"/>
    <motor name="FR_calf_joint" joint="FR_calf_joint"/>
    <motor name="RR_calf_joint" joint="RR_calf_joint"/> -->

    <motor name="FR_hip_joint" joint="FR_hip_joint"/>
    <motor name="FR_thigh_joint" joint="FR_thigh_joint"/>
    <motor name="FR_calf_joint" joint="FR_calf_joint"/>

    <motor name="FL_hip_joint" joint="FL_hip_joint"/>
    <motor name="FL_thigh_joint" joint="FL_thigh_joint"/>
    <motor name="FL_calf_joint" joint="FL_calf_joint"/>

    <motor name="RR_hip_joint" joint="RR_hip_joint"/>
    <motor name="RR_thigh_joint" joint="RR_thigh_joint"/>
    <motor name="RR_calf_joint" joint="RR_calf_joint"/>

    <motor name="RL_hip_joint" joint="RL_hip_joint"/>
    <motor name="RL_thigh_joint" joint="RL_thigh_joint"/>
    <motor name="RL_calf_joint" joint="RL_calf_joint"/>

  </actuator>
</mujoco>
